<?xml version="1.0" ?>
<!-- =================================================================================== -->
<!-- |    This document was autogenerated by xacro from /home/kathan/Desktop/hulku_bot/src/arm_description/description/bot.urdf.xacro | -->
<!-- |    EDITING THIS FILE BY HAND IS NOT RECOMMENDED                                 | -->
<!-- =================================================================================== -->
<robot name="robot">
  <!-- Specify some standard inertial calculations https://en.wikipedia.org/wiki/List_of_moments_of_inertia -->
  <!-- These make use of xacro's mathematical functionality -->
  <material name="white">
    <color rgba="1 1 1 0.7"/>
  </material>
  <material name="orange">
    <color rgba="1 0.5 0 0.7"/>
  </material>
  <material name="blue">
    <color rgba="0 0 1 0.7"/>
  </material>
  <material name="green">
    <color rgba="0 1 0 0.7"/>
  </material>
  <material name="black">
    <color rgba="0 0 0 0.7"/>
  </material>
  <material name="red">
    <color rgba="1 0 0 0.7"/>
  </material>
  <!-- BASE LINK -->
  <link name="base_link">
    <visual>
      <geometry>
        <box size="0.001 0.001 0.001"/>
      </geometry>
      <material name="white"/>
    </visual>
  </link>
  <!-- base footprint -->
  <joint name="base_footprint_joint" type="fixed">
    <parent link="base_link"/>
    <child link="base_footprint"/>
    <origin rpy="0 0 0" xyz="0 0 0"/>
  </joint>
  <link name="base_footprint">
    <visual>
      <geometry>
        <box size="0.001 0.001 0.001"/>
      </geometry>
      <material name="white"/>
    </visual>
  </link>
  <!-- base cylinder -->
  <joint name="base_cylinder_joint" type="fixed">
    <parent link="base_link"/>
    <child link="base_cylinder"/>
    <origin rpy="0 0 0" xyz="0 0 0.104"/>
  </joint>
  <link name="base_cylinder">
    <visual>
      <origin rpy="0 0 0" xyz="0 0 -0.0655"/>
      <geometry>
        <cylinder length="0.077" radius="0.040"/>
      </geometry>
      <material name="green"/>
    </visual>
    <collision>
      <origin rpy="0 0 0" xyz="0 0 -0.0655"/>
      <geometry>
        <cylinder length="0.077" radius="0.040"/>
      </geometry>
      <material name="green"/>
    </collision>
    <inertial>
      <origin rpy="0 0 0" xyz="0 0 -0.0655"/>
      <mass value="0.1"/>
      <inertia ixx="8.940833333333333e-05" ixy="0.0" ixz="0.0" iyy="8.940833333333333e-05" iyz="0.0" izz="8e-05"/>
    </inertial>
  </link>
  <!-- link 1 -->
  <joint name="link_1_joint" type="revolute">
    <parent link="base_cylinder"/>
    <child link="link_1"/>
    <origin rpy="0 0 0" xyz="0 0 0"/>
    <axis xyz="0 0 1"/>
    <limit effort="100" lower="-1.5707963267948966" upper="1.5707963267948966" velocity="1"/>
  </joint>
  <link name="link_1">
    <visual>
      <origin rpy="0 0 0" xyz="0 0 -0.0215"/>
      <geometry>
        <box size="0.021 0.0415 0.011"/>
      </geometry>
      <material name="blue"/>
    </visual>
    <collision>
      <origin rpy="0 0 0" xyz="0 0 -0.0215"/>
      <geometry>
        <box size="0.021 0.0415 0.011"/>
      </geometry>
      <material name="blue"/>
    </collision>
    <inertial>
      <origin rpy="0 0 0" xyz="0 0 -0.0215"/>
      <mass value="0.1"/>
      <inertia ixx="1.536041666666667e-05" ixy="0.0" ixz="0.0" iyy="4.683333333333333e-06" iyz="0.0" izz="1.8027083333333336e-05"/>
    </inertial>
  </link>
  <!-- link 2 -->
  <joint name="link_2_joint" type="revolute">
    <parent link="link_1"/>
    <child link="link_2"/>
    <origin rpy="1.5707963267948966 -1.5707963267948966 0" xyz="0 0 0"/>
    <axis xyz="0 0 1"/>
    <limit effort="100" lower="-1.5707963267948966" upper="1.5707963267948966" velocity="1"/>
  </joint>
  <link name="link_2">
    <visual>
      <origin rpy="1.5707963267948966 0 -1.5707963267948966" xyz="0.02875 0 0"/>
      <geometry>
        <box size="0.021 0.0415 0.0785"/>
      </geometry>
      <material name="blue"/>
    </visual>
    <collision>
      <origin rpy="1.5707963267948966 0 -1.5707963267948966" xyz="0.02875 0 0"/>
      <geometry>
        <box size="0.021 0.0415 0.0785"/>
      </geometry>
      <material name="blue"/>
    </collision>
    <inertial>
      <origin rpy="1.5707963267948966 0 -1.5707963267948966" xyz="0.02875 0 0"/>
      <mass value="0.1"/>
      <inertia ixx="6.570416666666667e-05" ixy="0.0" ixz="0.0" iyy="5.502708333333334e-05" iyz="0.0" izz="1.8027083333333336e-05"/>
    </inertial>
  </link>
  <!-- link 3 -->
  <joint name="link_3_joint" type="revolute">
    <parent link="link_2"/>
    <child link="link_3"/>
    <origin rpy="0 0 0" xyz="0.084 0 0."/>
    <axis xyz="0 0 1"/>
    <limit effort="100" lower="-1.5707963267948966" upper="1.5707963267948966" velocity="1"/>
  </joint>
  <link name="link_3">
    <visual>
      <origin rpy="1.5707963267948966 0 -1.5707963267948966" xyz="0.02775 0 0"/>
      <geometry>
        <box size="0.021 0.0415 0.0765"/>
      </geometry>
      <material name="blue"/>
    </visual>
    <collision>
      <origin rpy="1.5707963267948966 0 -1.5707963267948966" xyz="0.02775 0 0"/>
      <geometry>
        <box size="0.021 0.0415 0.0765"/>
      </geometry>
      <material name="blue"/>
    </collision>
    <inertial>
      <origin rpy="1.5707963267948966 0 -1.5707963267948966" xyz="0.02775 0 0"/>
      <mass value="0.1"/>
      <inertia ixx="6.312083333333333e-05" ixy="0.0" ixz="0.0" iyy="5.2443750000000004e-05" iyz="0.0" izz="1.8027083333333336e-05"/>
    </inertial>
  </link>
  <!-- link 4 -->
  <joint name="link_4_joint" type="revolute">
    <parent link="link_3"/>
    <child link="link_4"/>
    <origin rpy="0 0 0" xyz="0.082 0 0"/>
    <axis xyz="0 0 1"/>
    <limit effort="100" lower="-1.5707963267948966" upper="1.5707963267948966" velocity="1"/>
  </joint>
  <link name="link_4">
    <visual>
      <origin rpy="1.5707963267948966 0 -1.5707963267948966" xyz="0.03175 0 0"/>
      <geometry>
        <box size="0.021 0.0415 0.0845"/>
      </geometry>
      <material name="blue"/>
    </visual>
    <collision>
      <origin rpy="1.5707963267948966 0 -1.5707963267948966" xyz="0.03175 0 0"/>
      <geometry>
        <box size="0.021 0.0415 0.0845"/>
      </geometry>
      <material name="blue"/>
    </collision>
    <inertial>
      <origin rpy="1.5707963267948966 0 -1.5707963267948966" xyz="0.03175 0 0"/>
      <mass value="0.1"/>
      <inertia ixx="7.385416666666668e-05" ixy="0.0" ixz="0.0" iyy="6.317708333333334e-05" iyz="0.0" izz="1.8027083333333336e-05"/>
    </inertial>
  </link>
  <!-- EEpin -->
  <joint name="ee_pin_joint" type="fixed">
    <parent link="link_4"/>
    <child link="ee_pin"/>
    <!-- <origin xyz="-0.01 0.070 0.012" rpy="-${pi/2} 0 0" /> -->
    <origin rpy="-1.5707963267948966  0 -1.5707963267948966" xyz="0.086 0.010 -0.012"/>
  </joint>
  <link name="ee_pin">
    <visual>
      <origin rpy="0 0 0" xyz="0 0 -0.006"/>
      <geometry>
        <box size="0.001 0.001 0.012"/>
      </geometry>
      <material name="white"/>
    </visual>
    <collision>
      <origin rpy="0 0 0" xyz="0 0 -0.006"/>
      <geometry>
        <box size="0.001 0.001 0.012"/>
      </geometry>
      <material name="white"/>
    </collision>
    <inertial>
      <origin rpy="0 0 0" xyz="0 0 -0.006"/>
      <mass value="0.1"/>
      <inertia ixx="1.2083333333333333e-06" ixy="0.0" ixz="0.0" iyy="1.2083333333333333e-06" iyz="0.0" izz="1.6666666666666667e-08"/>
    </inertial>
  </link>
  <!-- left-finger -->
  <!-- <joint name="left_finger_joint" type="prismatic">
        <parent link="link_4"/>
        <child link="left_finger"/>
        <origin xyz="0 0 0.091" rpy="0 0 0" />
        <axis xyz="0 1 0"/>
        <limit lower="0.006" upper="0.025" effort="100" velocity="1"/>
    </joint>

    <link name="left_finger">
        <visual>
            <origin xyz="0 0 0" rpy="0 0 0" />
            <geometry>
                <box size="0.022 0.011 0.040"/>
            </geometry>
            <material name="blue"/>
        </visual>
        <collision>
            <origin xyz="0 0 0" rpy="0 0 0" />
            <geometry>
                <box size="0.022 0.011 0.040"/>
            </geometry>
            <material name="blue"/>
        </collision>
        <xacro:inertial_box mass="0.1" x="0.022" y="0.011" z="0.040">
            <origin xyz="0 0 0" rpy="0 0 0" />
        </xacro:inertial_box>
    </link> -->
  <!-- right-finger -->
  <!-- <joint name="right_finger_joint" type="prismatic">
        <parent link="link_4"/>
        <child link="right_finger"/>
        <origin xyz="0 0 0.091" rpy="0 0 0" />
        <axis xyz="0 1 0"/>
        <mimic joint="left_finger_joint" multiplier="-1.0" offset="0" />
        <limit lower="-0.025" upper="-0.006" effort="100" velocity="1"/>
    </joint>

    <link name="right_finger">
        <visual>
            <origin xyz="0 0 0" rpy="0 0 0" />
            <geometry>
                <box size="0.022 0.011 0.040"/>
            </geometry>
            <material name="blue"/>
        </visual>
        <collision>
            <origin xyz="0 0 0" rpy="0 0 0" />
            <geometry>
                <box size="0.022 0.011 0.040"/>
            </geometry>
            <material name="blue"/>
        </collision>
        <xacro:inertial_box mass="0.1" x="0.022" y="0.011" z="0.040">
            <origin xyz="0 0 0" rpy="0 0 0" />
        </xacro:inertial_box>
    </link> -->
  <!-- <xacro:include filename="gazebo_control.xacro" /> -->
  <!-- <xacro:include filename="lidar.xacro" /> -->
  <!--  -->
  <!-- <xacro:include filename="camera.xacro" /> -->
  <!-- <xacro:include filename="depth_camera.xacro" /> -->
</robot>
